<?xml version="1.0"?>
<robot name="robot_arm" xmlns:xacro="https://ww.ros.org/wiki/xacro">

    <xacro:include filename="inertia.urdf.xacro"/>
    <!-- Include Gazebo Parameters -->
    <xacro:include filename="gazebo.xacro"/>

    <!-- Include ros2_control Plugins -->
    <xacro:include filename="robot_arm_ros2_control.xacro"/>

    <xacro:property name="PI" value="3.14159265359" />
    <xacro:property name="effort" value="30.0" />
    <xacro:property name="velocity" value="10.0" />

    <xacro:macro name="default_transmission" params="number">
        <transmission name="transmission_${number}">
            <plugin>transmission_interface/SimpleTransmission</plugin>
            <actuator name="motor_${number}" role="actuator1"/>
            <joint name="joint${number}"    role="joint1">
                <mechanical_reduction>1.0</mechanical_reduction>
            </joint>
        </transmission>
    </xacro:macro>


    <link name="world"/>

    <joint name="joint1" type="continuous">
        <origin xyz="0.0 0.0 0.0" rpy="0.0 0.0 0.0"/>
        <parent link="world"/>
        <child link="a1"/>
        <axis xyz="0.0 0.0 1.0"/>
        <limit lower="-${PI}" upper="${PI}" 
                effort="${effort}" velocity="${velocity}"/>
        <ros2_control>
            <hardwareInterface>hardware_interface/PositionJointInterface</hardwareInterface>
        </ros2_control>
    </joint>

    <link name="a1">
        <xacro:inertial_cylinder mass="0.5" length="5.0" radius="0.05">
            <origin xyz="0.0 0 2.5" rpy="0 0 0"/>
        </xacro:inertial_cylinder>
        <visual name="">
            <origin xyz="0.0 0.0 2.5" rpy="0.0 0.0 0.0"/>
            <geometry>
                <cylinder radius="0.05" length="5.0"/>
            </geometry>
            <material name="">
                <color rgba="1.0 0.0 0.0 1.0"/>
                <!-- <texture filename=""/> -->
            </material>
        </visual>
        <collision>
            <origin xyz="0.0 0.0 2.5" rpy="0.0 0.0 0.0"/>
            <geometry>
                <cylinder radius="0.05" length="5.0"/>
            </geometry>
        </collision>
    </link>

    <joint name="joint2" type="continuous">
        <origin xyz="0.0 0.1 5.0" rpy="0.0 0.0 0.0"/>
        <parent link="a1"/>
        <child link="a2"/>
        <axis xyz="0.0 1.0 0.0"/>
        <!-- <limit lower="0.0" upper="0.0" effort="0.0" velocity="0.0"/> -->
        <limit lower="-${PI/2}" upper="${PI/2}" 
                effort="${effort}" velocity="${velocity}"/>
        <ros2_control>
            <hardwareInterface>hardware_interface/PositionJointInterface</hardwareInterface>
        </ros2_control>
    </joint>

    <link name="a2">
        <xacro:inertial_cylinder mass="0.3" length="3.0" radius="0.05">
            <origin xyz="1.5 0 0.0" rpy="0 1.57 0"/>
        </xacro:inertial_cylinder>
        <visual name="">
            <origin xyz="1.5 0.0 0.0" rpy="0.0 1.57 0.0"/>
            <geometry>
                <cylinder radius="0.05" length="3.0"/>
            </geometry>
            <material name="">
                <color rgba="1.0 1.0 0.0 1.0"/>
            </material>
        </visual>
        <collision>
            <origin xyz="1.5 0.0 0.0" rpy="0.0 1.57 0.0"/>
            <geometry>
                <cylinder radius="0.05" length="3.0"/>
            </geometry>
        </collision>
    </link>

    <joint name="joint3" type="continuous">
        <origin xyz="3.0 -0.1 0.0" rpy="0.0 0.0 0.0"/>
        <parent link="a2"/>
        <child link="a3"/>
        <axis xyz="0.0 1.0 0.0"/>
        <limit lower="0.0" upper="${PI}" 
                effort="${effort}" velocity="${velocity}"/>
        <ros2_control>
            <hardwareInterface>hardware_interface/PositionJointInterface</hardwareInterface>
        </ros2_control>
    </joint>

    <link name="a3">
        <xacro:inertial_cylinder mass="0.2" length="2.0" radius="0.05">
            <origin xyz="1.0 0 0.0" rpy="0 1.57 0"/>
        </xacro:inertial_cylinder>
        <visual name="">
            <origin xyz="1.0 0.0 0.0" rpy="0.0 1.57 0.0"/>
            <geometry>
                <cylinder radius="0.05" length="2.0"/>
            </geometry>
            <material name="">
                <color rgba="0.0 1.0 1.0 1.0"/>
                <!-- <texture filename=""/> -->
            </material>
        </visual>
        <collision>
            <origin xyz="1.0 0.0 0.0" rpy="0.0 1.57 0.0"/>
            <geometry>
                <cylinder radius="0.05" length="2.0"/>
            </geometry>
        </collision>
    </link>

    <joint name="joint4" type="continuous">
        <origin xyz="2.0 0.0 0.0" rpy="0.0 0.0 0.0"/>
        <parent link="a3"/>
        <child link="a4"/>
        <axis xyz="0.0 1.0 0.0"/>
        <limit lower="-${PI/2}" upper="${PI/2}" 
               effort="${effort}" velocity="${velocity}"/>
        <ros2_control>
            <hardwareInterface>hardware_interface/PositionJointInterface</hardwareInterface>
        </ros2_control>
    </joint>

    <link name="a4">
        <xacro:inertial_cylinder mass="1.0" length="1.0" radius="0.05">
            <origin xyz="0.5 0 0.0" rpy="0 1.57 0"/>
        </xacro:inertial_cylinder>
        <visual name="">
            <origin xyz="0.5 0.0 0.0" rpy="0.0 1.57 0.0"/>
            <geometry>
                <cylinder radius="0.05" length="1.0"/>
            </geometry>
            <material name="">
                <color rgba="0.0 1.0 0.0 1.0"/>
                <!-- <texture filename=""/> -->
            </material>
        </visual>
        <collision>
            <origin xyz="0.5 0.0 0.0" rpy="0.0 1.57 0.0"/>
            <geometry>
                <cylinder radius="0.05" length="1.0"/>
            </geometry>
        </collision>
    </link>

    <!-- Transmissions-->
    <xacro:default_transmission number="1"/>
    <xacro:default_transmission number="2"/>
    <xacro:default_transmission number="3"/>
    <xacro:default_transmission number="4"/>

</robot>
